Workbook
Name ListaFuncionarios: 'FUNCIONÁRIOS'!$C$4:$C$997
Name ListaEmpresas: '📋 Empresas'!$B$4:$B$103

Sheet 📋 Empresas
A1: 🏢 CADASTRO DE EMPRESAS
A3: # | B3: EMPRESA | C3: RESPONSÁVEL | D3: TELEFONE | E3: E-MAIL | F3: OBSERVAÇÕES
A4: 1 | B4: PONCIANO SOLUÇÕES | C4: Leo Ponciano | D4: (62) 99999-0001 | E4: leo@ponciano.com.br
A5: 2 | B5: MONTE EVENTOS | C5: EDUARDO HENRIQUE | D5: (61) 99880-4657 | E5: -
A6: 3 | B6: UP MUSIC | C6: RODRIGO BORGES | D6: (00)00000-0000 | E6: -
A7: =4 -> 4 | B7: TJ SERVIÇOS | C7: JESSICA LUZENNYLDES | D7: 61982032161 | E7: tjservicosltda@gmail
A8: =5 -> 5 | B8: FLASH MED | C8: - | D8: - | E8: -
A9: =6 -> 6 | B9: YES | C9: - | D9: - | E9: -
A10: =7 -> 7 | B10: BIGODE | C10: - | D10: - | E10: -
A11: =8 -> 8 | B11: NLEDS LOCAÇÃO - PAINEIS DE LED | C11: ROBSON MARTINS | D11: 62 99971 8380 | E11: nledslocacoes1@gmail.com
A12: =9 -> 9 | B12: ASSOCIAÇÃO ASSUNÇÃO | C12: - | D12: - | E12: -
A13: =10 -> 10 | B13: FABINHO EVENTOS | C13: - | D13: - | E13: -
A14: =11 -> 11 | B14: LINQ | C14: - | D14: - | E14: -
A15: =12 -> 12 | B15: ELEMENT
A16: =13 -> 13 | B16: MIX GERADORES
A17: =14 -> 14 | B17: REISFORT
A18: =15 -> 15 | B18: EL SHADDAI
A19: =16 -> 16 | B19: GO TO
A20: =17 -> 17 | B20: LINE TAPE
A21: =18 -> 18 | B21: GYNLIGHT
A22: =19 -> 19 | B22: DB ESTRUTURA
A23: =20 -> 20 | B23: BIG LIMP
A24: =21 -> 21 | B24: SHOWNEWS
A25: =22 -> 22 | B25: GYN EVENTS
A26: =23 -> 23 | B26: MARIA COLHER DE PAU
A27: =24 -> 24 | B27: VOU DE CHURROS
A28: =25 -> 25 | B28: POPCORN E BENDITO MILHO
A29: =26 -> 26 | B29: CANA JOY
A30: =27 -> 27 | B30: PIZZA GYN
A31: =28 -> 28 | B31: BASE PRO EVENTOS
A32: =29 -> 29 | B32: KOMIKETO
A33: =30 -> 30 | B33: CALAI CHURROS
A34: =31 -> 31 | B34: DORORÔ
A35: =32 -> 32 | B35: GRUPO IZA
A36: =33 -> 33 | B36: LA ESTRUTURA
A37: =34 -> 34 | B37: LATINO
A38: =35 -> 35 | B38: CARVALHO FORROS
A39: =36 -> 36 | B39: VISUAL LIVE
A40: =37 -> 37 | B40: STUDIO K
A41: =38 -> 38 | B41: CANA JOY
...

Sheet FUNCIONÁRIOS
A1: 👤 CADASTRO DE FUNCIONÁRIOS
A3: # | B3: EMPRESA (selecione ▼) | C3: NOME COMPLETO | D3: FUNÇÃO / CARGO | E3: COORDENADOR? | F3: CPF | G3: TELEFONE | H3: ÁREA DE ACESSO
A4: 2 | B4: PONCIANO SOLUÇÕES | C4: ALICE RIBEIRO LEITE | D4: CREDENCIAMENTO | E4: NÃO | F4: 4620015121 | G4: 62982916484 | H4: TODOS
A5: 3 | B5: MONTE EVENTOS | C5: Juan Miguel | D5: MONTADOR | E5: NÃO | F5: 8952559100 | G5: 62998333684 | H5: TODOS
A6: 4 | B6: MONTE EVENTOS | C6: kauan de Souza Morais | D6: MONTADOR | E6: NÃO | F6: 9637889140 | G6: 61996107028 | H6: TODOS
A7: 5 | B7: MONTE EVENTOS | C7: Gustavo Danilo Costa Tavares | D7: MONTADOR | E7: NÃO | F7: 8419797154 | G7: 61992655463 | H7: TODOS
A8: 6 | B8: MONTE EVENTOS | C8: Luis Felipe Cruz da Silva | D8: MONTADOR | E8: NÃO | F8: 8072713140 | G8: 619858702161 | H8: TODOS
A9: 7 | B9: UP MUSIC | C9: ROBSON MORERIRA MARTINS | D9: PRODUTOR DE PALCO | E9: NÃO | F9: 591.817.451-68 | G9: 62999718380 | H9: TODOS
A10: 8 | B10: MONTE EVENTOS | C10: Hildebrando Ferreira de Souza | D10: MONTADOR | E10: NÃO | F10: 58377484153 | G10: 61998117475 | H10: TODOS
A11: 9 | B11: MONTE EVENTOS | C11: Yago Oliveira de Souza | D11: MONTADOR | E11: NÃO | F11: 7899703174 | G11: 61998117475 | H11: TODOS
A12: 10 | B12: MONTE EVENTOS | C12: Ruan Andrade Braga | D12: MONTADOR | E12: NÃO | F12: 7630645139 | G12: 61984536021 | H12: TODOS
A13: 11 | B13: MONTE EVENTOS | C13: Genário da conceição Diniz | D13: MONTADOR | E13: NÃO | F13: 9092993158 | G13: 619815309541 | H13: TODOS
A14: 12 | B14: MONTE EVENTOS | C14: Eduardo Henrique do lago Ramos | D14: COORDENADOR/CEO | E14: SIM | F14: 98158961134 | G14: 619988046571 | H14: TODOS
A15: 13 | B15: MONTE EVENTOS | C15: Alessandro santos da Silva | D15: MONTADOR | E15: NÃO | F15: 69755167153 | G15: 61992512129 | H15: TODOS
A16: 14 | B16: MONTE EVENTOS | C16: Taylon Vitor Soares de Alencar | D16: MONTADOR | E16: NÃO | F16: 2673333312 | G16: 61981746685 | H16: TODOS
A17: 15 | B17: MONTE EVENTOS | C17: Sidney Marcelinho Martins | D17: MONTADOR | E17: NÃO | F17: 3078304116 | G17: 62993467519 | H17: TODOS
A18: 16 | B18: MONTE EVENTOS | C18: Willames David Lima dos santos | D18: MONTADOR | E18: NÃO | F18: 123.443.794-52 | G18: 61991318333 | H18: TODOS
A19: 17 | B19: MONTE EVENTOS | C19: José Wellingtom | D19: MONTADOR | E19: NÃO | F19: 12716279497 | G19: 61982376265 | H19: TODOS
A20: 18 | B20: MONTE EVENTOS | C20: Leonardo de Andrade Estevão | D20: MONTADOR | E20: NÃO | F20: 7235181141 | G20: 61996704390 | H20: TODOS
A21: 19 | B21: MONTE EVENTOS | C21: Washington Carlos Nascimento Costa | D21: MONTADOR | E21: NÃO | F21: 7372119111 | G21: 61995712311 | H21: TODOS
A22: 20 | B22: MONTE EVENTOS | C22: Hananias Sousa Alves dos santos | D22: MONTADOR | E22: NÃO | F22: 2941450106 | G22: 61993972049 | H22: TODOS
A23: 21 | B23: MONTE EVENTOS | C23: Erik natan Lopes Machado | D23: MONTADOR | E23: NÃO | F23: 9829266184 | G23: 61993159807 | H23: TODOS
A24: 22 | B24: MONTE EVENTOS | C24: Renato de Araújo Morais | D24: MONTADOR | E24: NÃO | F24: 055480406-93 | G24: 61998524652 | H24: TODOS
A25: 23 | B25: MONTE EVENTOS | C25: Guilherme Silva dos Anjos | D25: MONTADOR | E25: NÃO | F25: 8480857102 | G25: 68974008638 | H25: TODOS
A26: 24 | B26: TJ SERVIÇOS | C26: Andressa Santana Dias | D26: BRIGADISTA | E26: NÃO | F26: 71041320177 | G26: 62994398006 | H26: TODOS
A27: 25 | B27: TJ SERVIÇOS | C27: JESSICA LUZENNYLDES GOUVEIA FERREIRA | D27: COORDENADOR/CEO | E27: SIM | F27: 3325063209 | G27: 61982032161 | H27: TODOS
A28: 26 | B28: TJ SERVIÇOS | C28: Marília de Jesus honorato | D28: BRIGADISTA | E28: NÃO | F28: 2768398110 | G28: 62982800037 | H28: TODOS
A29: 27 | B29: FLASH MED | C29: Edna Maria da Silva Olívia | D29: SOCORRITA | E29: NÃO | F29: 38086379191 | G29: 62991017458 | H29: TODOS
A30: 28 | B30: FLASH MED | C30: Ricardo Souza dos santos | D30: SOCORRITA | E30: NÃO | F30: 83961712115 | G30: 62984819874 | H30: TODOS
A31: 29 | B31: YES | C31: Wagner Martins lira | D31: TEC SEGURANÇA | E31: NÃO | F31: 69557764104 | G31: 62994720044 | H31: TODOS
A32: 30 | B32: UP MUSIC | C32: Fernando Rosa dos Reis | D32: PRODUTOR | E32: NÃO | F32: 711022152 | H32: TODOS
A33: 31 | B33: BIGODE | C33: Vinicius Monteiro Silva | D33: CONTROLE DE ACESSO | E33: NÃO | F33: 908970137 | G33: 62998060973 | H33: TODOS
A34: 32 | B34: BIGODE | C34: Ronara Moreira Borges Meireles | D34: CONTROLE DE ACESSO | E34: NÃO | F34: 6530814132 | G34: 62994417671 | H34: TODOS
A35: 33 | C35: KLEBIO DOS REIS SILVA | D35: OPERADOR DE EMPILHADEIRA | E35: NÃO | F35: 854518193 | G35: 62982259494 | H35: TODOS
A36: 34 | B36: NLEDS LOCAÇÃO - PAINEIS DE LED | C36: FELIPE ALVES ANGELI | D36: TÉCNICO DE MONTAGEM DE PAINÉIS DE LED | E36: NÃO | F36: 701.526.281-93 | H36: TODOS
A37: 35 | B37: NLEDS LOCAÇÃO - PAINEIS DE LED | C37: DEYVID DA SILVA RODRIGUES | D37: TÉCNICO DE MONTAGEM DE PAINÉIS DE LED | E37: NÃO | F37: 705.433.931-27 | H37: TODOS
A38: 36 | B38: NLEDS LOCAÇÃO - PAINEIS DE LED | C38: CARLOS DANIEL VIEIRA DOS REIS | D38: AUXILIAR DE MONTAGEM DE PAINÉIS DE LED | E38: NÃO | F38: 713.992.111-37 | H38: TODOS
A39: 37 | B39: NLEDS LOCAÇÃO - PAINEIS DE LED | C39: LUCAS RODRIGUES DA SILVA | D39: AUXILIAR DE MONTAGEM DE PAINÉIS DE LED | E39: NÃO | F39: 059.746.271-21 | H39: TODOS
A40: 38 | B40: NLEDS LOCAÇÃO - PAINEIS DE LED | C40: LUIZ GUSTAVO DOS REIS MORAES | D40: AUXILIAR DE MONTAGEM DE PAINÉIS DE LED | E40: NÃO | F40: 077.414.661-35 | H40: TODOS
A41: 39 | B41: NLEDS LOCAÇÃO - PAINEIS DE LED | C41: RIVALDO NUNES DA SILVA | D41: AUXILIAR DE MONTAGEM DE PAINÉIS DE LED | E41: NÃO | F41: 909.034.121-87 | H41: TODOS
...

Sheet ⏱️ Entrada e Saída
A1: ⏱️ CONTROLE DE ENTRADA E SAÍDA — EVENTO
A3: # | B3: NOME (selecione ▼) | C3: EMPRESA | D3: FUNÇÃO | E3: COORD.? | F3: DATA | G3: ⏺ MARCAR ENTRADA (via Menu ⏱️ Ponto) | H3: ENTRADA | I3: ⏺ MARCAR SAÍDA (via Menu ⏱️ Ponto) | J3: SAÍDA | K3: ⏳ HORAS | L3: STATUS
A4: =2 -> 2 | B4: ALICE RIBEIRO LEITE | C4: {=IF(B4="","",IFERROR(INDEX('FUNCIONÁRIOS'!$B$4:$B$501,MATCH(B4,'FUNCIONÁRIOS'!$C$4:$C$501,0)),""))} -> PONCIANO SOLUÇÕES | D4: {=IF(B4="","",IFERROR(INDEX('FUNCIONÁRIOS'!$D$4:$D$501,MATCH(B4,'FUNCIONÁRIOS'!$C$4:$C$501,0)),""))} -> CREDENCIAMENTO | E4: {=IF(B4="","",IFERROR(INDEX('FUNCIONÁRIOS'!$E$4:$E$501,MATCH(B4,'FUNCIONÁRIOS'!$C$4:$C$501,0)),""))} -> NÃO | F4: 46160 | G4: =IF(H4<>"","✅ "&TEXT(H4,"HH:MM"),"→ Selecione a linha e use o menu ⏱️ Ponto") -> ✅ 07:30 | H4: 07:30 | I4: =IF(J4<>"","✅ "&TEXT(J4,"HH:MM"),"→ Selecione a linha e use o menu ⏱️ Ponto") -> ✅ 17:43 | J4: 17:43 | K4: =IF(AND(H4<>"",J4<>""),J4-H4,"") -> 0.42569444 | L4: =IF(AND(H4<>"",J4=""),"🟢 No Evento",IF(AND(H4<>"",J4<>""),"✅ Finalizado",IF(B4<>"","⏳ Não entrou",""))) -> ✅ Finalizado
B5: KLEBIO DOS REIS SILVA | C5: - | D5: OPERADOR DE EMPILHADEIRA | E5: NÃO | F5: 46160 | G5: =IF(H5<>"","✅ "&TEXT(H5,"HH:MM"),"→ Selecione a linha e use o menu ⏱️ Ponto") -> ✅ 08:00 | H5: 08:00 | I5: =IF(J5<>"","✅ "&TEXT(J5,"HH:MM"),"→ Selecione a linha e use o menu ⏱️ Ponto") -> ✅ 17:19 | J5: 17:19 | K5: 0.38263889 | L5: =IF(AND(H5<>"",J5=""),"🟢 No Evento",IF(AND(H5<>"",J5<>""),"✅ Finalizado",IF(B5<>"","⏳ Não entrou",""))) -> ✅ Finalizado
A6: =3 -> 3 | B6: Juan Miguel | C6: {=IF(B6="","",IFERROR(INDEX('FUNCIONÁRIOS'!$B$4:$B$501,MATCH(B6,'FUNCIONÁRIOS'!$C$4:$C$501,0)),""))} -> MONTE EVENTOS | D6: {=IF(B6="","",IFERROR(INDEX('FUNCIONÁRIOS'!$D$4:$D$501,MATCH(B6,'FUNCIONÁRIOS'!$C$4:$C$501,0)),""))} -> MONTADOR | E6: {=IF(B6="","",IFERROR(INDEX('FUNCIONÁRIOS'!$E$4:$E$501,MATCH(B6,'FUNCIONÁRIOS'!$C$4:$C$501,0)),""))} -> NÃO | F6: 46160 | G6: =IF(H6<>"","✅ "&TEXT(H6,"HH:MM"),"→ Selecione a linha e use o menu ⏱️ Ponto") -> ✅ 08:00 | H6: 08:00 | I6: =IF(J6<>"","✅ "&TEXT(J6,"HH:MM"),"→ Selecione a linha e use o menu ⏱️ Ponto") -> ✅ 17:17 | J6: 17:17 | K6: 0.38541667 | L6: =IF(AND(H6<>"",J6=""),"🟢 No Evento",IF(AND(H6<>"",J6<>""),"✅ Finalizado",IF(B6<>"","⏳ Não entrou",""))) -> ✅ Finalizado
A7: =4 -> 4 | B7: ROBSON MORERIRA MARTINS | C7: UP MUSIC | D7: {=IF(B7="","",IFERROR(INDEX('FUNCIONÁRIOS'!$D$4:$D$501,MATCH(B7,'FUNCIONÁRIOS'!$C$4:$C$501,0)),""))} -> PRODUTOR DE PALCO | E7: {=IF(B7="","",IFERROR(INDEX('FUNCIONÁRIOS'!$E$4:$E$501,MATCH(B7,'FUNCIONÁRIOS'!$C$4:$C$501,0)),""))} -> NÃO | F7: 46160 | G7: =IF(H7<>"","✅ "&TEXT(H7,"HH:MM"),"→ Selecione a linha e use o menu ⏱️ Ponto") -> ✅ 11:36 | H7: 11:36 | I7: =IF(J7<>"","✅ "&TEXT(J7,"HH:MM"),"→ Selecione a linha e use o menu ⏱️ Ponto") -> ✅ 17:00 | J7: 0.70833333 | K7: 0.275 | L7: =IF(AND(H7<>"",J7=""),"🟢 No Evento",IF(AND(H7<>"",J7<>""),"✅ Finalizado",IF(B7<>"","⏳ Não entrou",""))) -> ✅ Finalizado
A8: =5 -> 5 | B8: JESSICA LUZENNYLDES GOUVEIA FERREIRA | C8: {=IF(B8="","",IFERROR(INDEX('FUNCIONÁRIOS'!$B$4:$B$501,MATCH(B8,'FUNCIONÁRIOS'!$C$4:$C$501,0)),""))} -> TJ SERVIÇOS | D8: {=IF(B8="","",IFERROR(INDEX('FUNCIONÁRIOS'!$D$4:$D$501,MATCH(B8,'FUNCIONÁRIOS'!$C$4:$C$501,0)),""))} -> COORDENADOR/CEO | E8: {=IF(B8="","",IFERROR(INDEX('FUNCIONÁRIOS'!$E$4:$E$501,MATCH(B8,'FUNCIONÁRIOS'!$C$4:$C$501,0)),""))} -> SIM | F8: 46160 | G8: =IF(H8<>"","✅ "&TEXT(H8,"HH:MM"),"→ Selecione a linha e use o menu ⏱️ Ponto") -> ✅ 08:00 | H8: 0.33333333 | I8: =IF(J8<>"","✅ "&TEXT(J8,"HH:MM"),"→ Selecione a linha e use o menu ⏱️ Ponto") -> ✅ 16:31 | J8: 16:31 | K8: 0.35486111 | L8: =IF(AND(H8<>"",J8=""),"🟢 No Evento",IF(AND(H8<>"",J8<>""),"✅ Finalizado",IF(B8<>"","⏳ Não entrou",""))) -> ✅ Finalizado
A9: =6 -> 6 | B9: Kauan de Souza Morais | C9: {=IF(B9="","",IFERROR(INDEX('FUNCIONÁRIOS'!$B$4:$B$501,MATCH(B9,'FUNCIONÁRIOS'!$C$4:$C$501,0)),""))} -> MONTE EVENTOS | D9: {=IF(B9="","",IFERROR(INDEX('FUNCIONÁRIOS'!$D$4:$D$501,MATCH(B9,'FUNCIONÁRIOS'!$C$4:$C$501,0)),""))} -> MONTADOR | E9: {=IF(B9="","",IFERROR(INDEX('FUNCIONÁRIOS'!$E$4:$E$501,MATCH(B9,'FUNCIONÁRIOS'!$C$4:$C$501,0)),""))} -> NÃO | F9: 46160 | G9: =IF(H9<>"","✅ "&TEXT(H9,"HH:MM"),"→ Selecione a linha e use o menu ⏱️ Ponto") -> ✅ 08:00 | H9: 0.33333333 | I9: =IF(J9<>"","✅ "&TEXT(J9,"HH:MM"),"→ Selecione a linha e use o menu ⏱️ Ponto") -> ✅ 17:17 | J9: 0.72013889 | K9: =IF(AND(H9<>"",J9<>""),J9-H9,"") -> 0.38680556 | L9: =IF(AND(H9<>"",J9=""),"🟢 No Evento",IF(AND(H9<>"",J9<>""),"✅ Finalizado",IF(B9<>"","⏳ Não entrou",""))) -> ✅ Finalizado
A10: =7 -> 7 | B10: Gustavo Danilo Costa Tavares | C10: {=IF(B10="","",IFERROR(INDEX('FUNCIONÁRIOS'!$B$4:$B$501,MATCH(B10,'FUNCIONÁRIOS'!$C$4:$C$501,0)),""))} -> MONTE EVENTOS | D10: {=IF(B10="","",IFERROR(INDEX('FUNCIONÁRIOS'!$D$4:$D$501,MATCH(B10,'FUNCIONÁRIOS'!$C$4:$C$501,0)),""))} -> MONTADOR | E10: {=IF(B10="","",IFERROR(INDEX('FUNCIONÁRIOS'!$E$4:$E$501,MATCH(B10,'FUNCIONÁRIOS'!$C$4:$C$501,0)),""))} -> NÃO | F10: 46160 | G10: =IF(H10<>"","✅ "&TEXT(H10,"HH:MM"),"→ Selecione a linha e use o menu ⏱️ Ponto") -> ✅ 08:01 | H10: 0.33402778 | I10: =IF(J10<>"","✅ "&TEXT(J10,"HH:MM"),"→ Selecione a linha e use o menu ⏱️ Ponto") -> ✅ 17:17 | J10: 0.72013889 | K10: =IF(AND(H10<>"",J10<>""),J10-H10,"") -> 0.38611111 | L10: =IF(AND(H10<>"",J10=""),"🟢 No Evento",IF(AND(H10<>"",J10<>""),"✅ Finalizado",IF(B10<>"","⏳ Não entrou",""))) -> ✅ Finalizado
A11: =8 -> 8 | B11: Luis Felipe Cruz da Silva | C11: {=IF(B11="","",IFERROR(INDEX('FUNCIONÁRIOS'!$B$4:$B$501,MATCH(B11,'FUNCIONÁRIOS'!$C$4:$C$501,0)),""))} -> MONTE EVENTOS | D11: {=IF(B11="","",IFERROR(INDEX('FUNCIONÁRIOS'!$D$4:$D$501,MATCH(B11,'FUNCIONÁRIOS'!$C$4:$C$501,0)),""))} -> MONTADOR | E11: {=IF(B11="","",IFERROR(INDEX('FUNCIONÁRIOS'!$E$4:$E$501,MATCH(B11,'FUNCIONÁRIOS'!$C$4:$C$501,0)),""))} -> NÃO | F11: 46160 | G11: =IF(H11<>"","✅ "&TEXT(H11,"HH:MM"),"→ Selecione a linha e use o menu ⏱️ Ponto") -> ✅ 08:02 | H11: 0.33472222 | I11: =IF(J11<>"","✅ "&TEXT(J11,"HH:MM"),"→ Selecione a linha e use o menu ⏱️ Ponto") -> ✅ 17:17 | J11: 0.72013889 | K11: =IF(AND(H11<>"",J11<>""),J11-H11,"") -> 0.38541667 | L11: =IF(AND(H11<>"",J11=""),"🟢 No Evento",IF(AND(H11<>"",J11<>""),"✅ Finalizado",IF(B11<>"","⏳ Não entrou",""))) -> ✅ Finalizado
A12: =10 -> 10 | B12: Hildebrando Ferreira de Souza | C12: {=IF(B12="","",IFERROR(INDEX('FUNCIONÁRIOS'!$B$4:$B$501,MATCH(B12,'FUNCIONÁRIOS'!$C$4:$C$501,0)),""))} -> MONTE EVENTOS | D12: {=IF(B12="","",IFERROR(INDEX('FUNCIONÁRIOS'!$D$4:$D$501,MATCH(B12,'FUNCIONÁRIOS'!$C$4:$C$501,0)),""))} -> MONTADOR | E12: {=IF(B12="","",IFERROR(INDEX('FUNCIONÁRIOS'!$E$4:$E$501,MATCH(B12,'FUNCIONÁRIOS'!$C$4:$C$501,0)),""))} -> NÃO | F12: 46160 | G12: =IF(H12<>"","✅ "&TEXT(H12,"HH:MM"),"→ Selecione a linha e use o menu ⏱️ Ponto") -> ✅ 08:03 | H12: 0.33541667 | I12: =IF(J12<>"","✅ "&TEXT(J12,"HH:MM"),"→ Selecione a linha e use o menu ⏱️ Ponto") -> ✅ 17:12 | J12: 0.71666667 | K12: =IF(AND(H12<>"",J12<>""),J12-H12,"") -> 0.38125 | L12: =IF(AND(H12<>"",J12=""),"🟢 No Evento",IF(AND(H12<>"",J12<>""),"✅ Finalizado",IF(B12<>"","⏳ Não entrou",""))) -> ✅ Finalizado
A13: =11 -> 11 | B13: Yago Oliveira de Souza | C13: {=IF(B13="","",IFERROR(INDEX('FUNCIONÁRIOS'!$B$4:$B$501,MATCH(B13,'FUNCIONÁRIOS'!$C$4:$C$501,0)),""))} -> MONTE EVENTOS | D13: {=IF(B13="","",IFERROR(INDEX('FUNCIONÁRIOS'!$D$4:$D$501,MATCH(B13,'FUNCIONÁRIOS'!$C$4:$C$501,0)),""))} -> MONTADOR | E13: {=IF(B13="","",IFERROR(INDEX('FUNCIONÁRIOS'!$E$4:$E$501,MATCH(B13,'FUNCIONÁRIOS'!$C$4:$C$501,0)),""))} -> NÃO | F13: 46160 | G13: =IF(H13<>"","✅ "&TEXT(H13,"HH:MM"),"→ Selecione a linha e use o menu ⏱️ Ponto") -> ✅ 08:04 | H13: 0.33611111 | I13: =IF(J13<>"","✅ "&TEXT(J13,"HH:MM"),"→ Selecione a linha e use o menu ⏱️ Ponto") -> ✅ 17:18 | J13: 0.72083333 | K13: =IF(AND(H13<>"",J13<>""),J13-H13,"") -> 0.38472222 | L13: =IF(AND(H13<>"",J13=""),"🟢 No Evento",IF(AND(H13<>"",J13<>""),"✅ Finalizado",IF(B13<>"","⏳ Não entrou",""))) -> ✅ Finalizado
A14: =12 -> 12 | B14: Ruan Andrade Braga | C14: {=IF(B14="","",IFERROR(INDEX('FUNCIONÁRIOS'!$B$4:$B$501,MATCH(B14,'FUNCIONÁRIOS'!$C$4:$C$501,0)),""))} -> MONTE EVENTOS | D14: {=IF(B14="","",IFERROR(INDEX('FUNCIONÁRIOS'!$D$4:$D$501,MATCH(B14,'FUNCIONÁRIOS'!$C$4:$C$501,0)),""))} -> MONTADOR | E14: {=IF(B14="","",IFERROR(INDEX('FUNCIONÁRIOS'!$E$4:$E$501,MATCH(B14,'FUNCIONÁRIOS'!$C$4:$C$501,0)),""))} -> NÃO | F14: 46160 | G14: =IF(H14<>"","✅ "&TEXT(H14,"HH:MM"),"→ Selecione a linha e use o menu ⏱️ Ponto") -> ✅ 08:05 | H14: 0.33680556 | I14: =IF(J14<>"","✅ "&TEXT(J14,"HH:MM"),"→ Selecione a linha e use o menu ⏱️ Ponto") -> ✅ 17:18 | J14: 0.72083333 | K14: =IF(AND(H14<>"",J14<>""),J14-H14,"") -> 0.38402778 | L14: =IF(AND(H14<>"",J14=""),"🟢 No Evento",IF(AND(H14<>"",J14<>""),"✅ Finalizado",IF(B14<>"","⏳ Não entrou",""))) -> ✅ Finalizado
A15: =13 -> 13 | B15: Genário da conceição Diniz | C15: {=IF(B15="","",IFERROR(INDEX('FUNCIONÁRIOS'!$B$4:$B$501,MATCH(B15,'FUNCIONÁRIOS'!$C$4:$C$501,0)),""))} -> MONTE EVENTOS | D15: {=IF(B15="","",IFERROR(INDEX('FUNCIONÁRIOS'!$D$4:$D$501,MATCH(B15,'FUNCIONÁRIOS'!$C$4:$C$501,0)),""))} -> MONTADOR | E15: {=IF(B15="","",IFERROR(INDEX('FUNCIONÁRIOS'!$E$4:$E$501,MATCH(B15,'FUNCIONÁRIOS'!$C$4:$C$501,0)),""))} -> NÃO | F15: 46160 | G15: =IF(H15<>"","✅ "&TEXT(H15,"HH:MM"),"→ Selecione a linha e use o menu ⏱️ Ponto") -> ✅ 08:06 | H15: 0.3375 | I15: =IF(J15<>"","✅ "&TEXT(J15,"HH:MM"),"→ Selecione a linha e use o menu ⏱️ Ponto") -> ✅ 17:18 | J15: 0.72083333 | K15: =IF(AND(H15<>"",J15<>""),J15-H15,"") -> 0.38333333 | L15: =IF(AND(H15<>"",J15=""),"🟢 No Evento",IF(AND(H15<>"",J15<>""),"✅ Finalizado",IF(B15<>"","⏳ Não entrou",""))) -> ✅ Finalizado
A16: =14 -> 14 | B16: Eduardo Henrique do lago Ramos | C16: {=IF(B16="","",IFERROR(INDEX('FUNCIONÁRIOS'!$B$4:$B$501,MATCH(B16,'FUNCIONÁRIOS'!$C$4:$C$501,0)),""))} -> MONTE EVENTOS | D16: {=IF(B16="","",IFERROR(INDEX('FUNCIONÁRIOS'!$D$4:$D$501,MATCH(B16,'FUNCIONÁRIOS'!$C$4:$C$501,0)),""))} -> COORDENADOR/CEO | E16: {=IF(B16="","",IFERROR(INDEX('FUNCIONÁRIOS'!$E$4:$E$501,MATCH(B16,'FUNCIONÁRIOS'!$C$4:$C$501,0)),""))} -> SIM | F16: 46160 | G16: =IF(H16<>"","✅ "&TEXT(H16,"HH:MM"),"→ Selecione a linha e use o menu ⏱️ Ponto") -> ✅ 08:07 | H16: 0.33819444 | I16: =IF(J16<>"","✅ "&TEXT(J16,"HH:MM"),"→ Selecione a linha e use o menu ⏱️ Ponto") -> ✅ 17:18 | J16: 0.72083333 | K16: =IF(AND(H16<>"",J16<>""),J16-H16,"") -> 0.38263889 | L16: =IF(AND(H16<>"",J16=""),"🟢 No Evento",IF(AND(H16<>"",J16<>""),"✅ Finalizado",IF(B16<>"","⏳ Não entrou",""))) -> ✅ Finalizado
A17: =15 -> 15 | B17: Alessandro santos da Silva | C17: {=IF(B17="","",IFERROR(INDEX('FUNCIONÁRIOS'!$B$4:$B$501,MATCH(B17,'FUNCIONÁRIOS'!$C$4:$C$501,0)),""))} -> MONTE EVENTOS | D17: {=IF(B17="","",IFERROR(INDEX('FUNCIONÁRIOS'!$D$4:$D$501,MATCH(B17,'FUNCIONÁRIOS'!$C$4:$C$501,0)),""))} -> MONTADOR | E17: {=IF(B17="","",IFERROR(INDEX('FUNCIONÁRIOS'!$E$4:$E$501,MATCH(B17,'FUNCIONÁRIOS'!$C$4:$C$501,0)),""))} -> NÃO | F17: 46160 | G17: =IF(H17<>"","✅ "&TEXT(H17,"HH:MM"),"→ Selecione a linha e use o menu ⏱️ Ponto") -> ✅ 08:08 | H17: 0.33888889 | I17: =IF(J17<>"","✅ "&TEXT(J17,"HH:MM"),"→ Selecione a linha e use o menu ⏱️ Ponto") -> ✅ 17:19 | J17: 0.72152778 | K17: =IF(AND(H17<>"",J17<>""),J17-H17,"") -> 0.38263889 | L17: =IF(AND(H17<>"",J17=""),"🟢 No Evento",IF(AND(H17<>"",J17<>""),"✅ Finalizado",IF(B17<>"","⏳ Não entrou",""))) -> ✅ Finalizado
A18: =16 -> 16 | B18: Taylon Vitor Soares de Alencar | C18: {=IF(B18="","",IFERROR(INDEX('FUNCIONÁRIOS'!$B$4:$B$501,MATCH(B18,'FUNCIONÁRIOS'!$C$4:$C$501,0)),""))} -> MONTE EVENTOS | D18: {=IF(B18="","",IFERROR(INDEX('FUNCIONÁRIOS'!$D$4:$D$501,MATCH(B18,'FUNCIONÁRIOS'!$C$4:$C$501,0)),""))} -> MONTADOR | E18: {=IF(B18="","",IFERROR(INDEX('FUNCIONÁRIOS'!$E$4:$E$501,MATCH(B18,'FUNCIONÁRIOS'!$C$4:$C$501,0)),""))} -> NÃO | F18: 46160 | G18: =IF(H18<>"","✅ "&TEXT(H18,"HH:MM"),"→ Selecione a linha e use o menu ⏱️ Ponto") -> ✅ 08:09 | H18: 0.33958333 | I18: =IF(J18<>"","✅ "&TEXT(J18,"HH:MM"),"→ Selecione a linha e use o menu ⏱️ Ponto") -> ✅ 17:16 | J18: 0.71944444 | K18: =IF(AND(H18<>"",J18<>""),J18-H18,"") -> 0.37986111 | L18: =IF(AND(H18<>"",J18=""),"🟢 No Evento",IF(AND(H18<>"",J18<>""),"✅ Finalizado",IF(B18<>"","⏳ Não entrou",""))) -> ✅ Finalizado
A19: =17 -> 17 | B19: Sidney Marcelinho Martins | C19: {=IF(B19="","",IFERROR(INDEX('FUNCIONÁRIOS'!$B$4:$B$501,MATCH(B19,'FUNCIONÁRIOS'!$C$4:$C$501,0)),""))} -> MONTE EVENTOS | D19: {=IF(B19="","",IFERROR(INDEX('FUNCIONÁRIOS'!$D$4:$D$501,MATCH(B19,'FUNCIONÁRIOS'!$C$4:$C$501,0)),""))} -> MONTADOR | E19: {=IF(B19="","",IFERROR(INDEX('FUNCIONÁRIOS'!$E$4:$E$501,MATCH(B19,'FUNCIONÁRIOS'!$C$4:$C$501,0)),""))} -> NÃO | F19: 46160 | G19: =IF(H19<>"","✅ "&TEXT(H19,"HH:MM"),"→ Selecione a linha e use o menu ⏱️ Ponto") -> ✅ 08:10 | H19: 0.34027778 | I19: =IF(J19<>"","✅ "&TEXT(J19,"HH:MM"),"→ Selecione a linha e use o menu ⏱️ Ponto") -> ✅ 17:13 | J19: 0.71736111 | K19: =IF(AND(H19<>"",J19<>""),J19-H19,"") -> 0.37708333 | L19: =IF(AND(H19<>"",J19=""),"🟢 No Evento",IF(AND(H19<>"",J19<>""),"✅ Finalizado",IF(B19<>"","⏳ Não entrou",""))) -> ✅ Finalizado
A20: =18 -> 18 | B20: Willames David Lima dos santos | C20: {=IF(B20="","",IFERROR(INDEX('FUNCIONÁRIOS'!$B$4:$B$501,MATCH(B20,'FUNCIONÁRIOS'!$C$4:$C$501,0)),""))} -> MONTE EVENTOS | D20: {=IF(B20="","",IFERROR(INDEX('FUNCIONÁRIOS'!$D$4:$D$501,MATCH(B20,'FUNCIONÁRIOS'!$C$4:$C$501,0)),""))} -> MONTADOR | E20: {=IF(B20="","",IFERROR(INDEX('FUNCIONÁRIOS'!$E$4:$E$501,MATCH(B20,'FUNCIONÁRIOS'!$C$4:$C$501,0)),""))} -> NÃO | F20: 46160 | G20: =IF(H20<>"","✅ "&TEXT(H20,"HH:MM"),"→ Selecione a linha e use o menu ⏱️ Ponto") -> ✅ 08:11 | H20: 0.34097222 | I20: =IF(J20<>"","✅ "&TEXT(J20,"HH:MM"),"→ Selecione a linha e use o menu ⏱️ Ponto") -> ✅ 17:16 | J20: 0.71944444 | K20: =IF(AND(H20<>"",J20<>""),J20-H20,"") -> 0.37847222 | L20: =IF(AND(H20<>"",J20=""),"🟢 No Evento",IF(AND(H20<>"",J20<>""),"✅ Finalizado",IF(B20<>"","⏳ Não entrou",""))) -> ✅ Finalizado
A21: =19 -> 19 | B21: José Wellingtom | C21: {=IF(B21="","",IFERROR(INDEX('FUNCIONÁRIOS'!$B$4:$B$501,MATCH(B21,'FUNCIONÁRIOS'!$C$4:$C$501,0)),""))} -> MONTE EVENTOS | D21: {=IF(B21="","",IFERROR(INDEX('FUNCIONÁRIOS'!$D$4:$D$501,MATCH(B21,'FUNCIONÁRIOS'!$C$4:$C$501,0)),""))} -> MONTADOR | E21: {=IF(B21="","",IFERROR(INDEX('FUNCIONÁRIOS'!$E$4:$E$501,MATCH(B21,'FUNCIONÁRIOS'!$C$4:$C$501,0)),""))} -> NÃO | F21: 46160 | G21: =IF(H21<>"","✅ "&TEXT(H21,"HH:MM"),"→ Selecione a linha e use o menu ⏱️ Ponto") -> ✅ 08:12 | H21: 0.34166667 | I21: =IF(J21<>"","✅ "&TEXT(J21,"HH:MM"),"→ Selecione a linha e use o menu ⏱️ Ponto") -> ✅ 17:16 | J21: 0.71944444 | K21: =IF(AND(H21<>"",J21<>""),J21-H21,"") -> 0.37777778 | L21: =IF(AND(H21<>"",J21=""),"🟢 No Evento",IF(AND(H21<>"",J21<>""),"✅ Finalizado",IF(B21<>"","⏳ Não entrou",""))) -> ✅ Finalizado
A22: =20 -> 20 | B22: Leonardo de Andrade Estevão | C22: {=IF(B22="","",IFERROR(INDEX('FUNCIONÁRIOS'!$B$4:$B$501,MATCH(B22,'FUNCIONÁRIOS'!$C$4:$C$501,0)),""))} -> MONTE EVENTOS | D22: {=IF(B22="","",IFERROR(INDEX('FUNCIONÁRIOS'!$D$4:$D$501,MATCH(B22,'FUNCIONÁRIOS'!$C$4:$C$501,0)),""))} -> MONTADOR | E22: {=IF(B22="","",IFERROR(INDEX('FUNCIONÁRIOS'!$E$4:$E$501,MATCH(B22,'FUNCIONÁRIOS'!$C$4:$C$501,0)),""))} -> NÃO | F22: 46160 | G22: =IF(H22<>"","✅ "&TEXT(H22,"HH:MM"),"→ Selecione a linha e use o menu ⏱️ Ponto") -> ✅ 08:13 | H22: 0.34236111 | I22: =IF(J22<>"","✅ "&TEXT(J22,"HH:MM"),"→ Selecione a linha e use o menu ⏱️ Ponto") -> ✅ 17:14 | J22: 0.71805556 | K22: =IF(AND(H22<>"",J22<>""),J22-H22,"") -> 0.37569444 | L22: =IF(AND(H22<>"",J22=""),"🟢 No Evento",IF(AND(H22<>"",J22<>""),"✅ Finalizado",IF(B22<>"","⏳ Não entrou",""))) -> ✅ Finalizado
A23: =21 -> 21 | B23: Washington Carlos Nascimento Costa | C23: {=IF(B23="","",IFERROR(INDEX('FUNCIONÁRIOS'!$B$4:$B$501,MATCH(B23,'FUNCIONÁRIOS'!$C$4:$C$501,0)),""))} -> MONTE EVENTOS | D23: {=IF(B23="","",IFERROR(INDEX('FUNCIONÁRIOS'!$D$4:$D$501,MATCH(B23,'FUNCIONÁRIOS'!$C$4:$C$501,0)),""))} -> MONTADOR | E23: {=IF(B23="","",IFERROR(INDEX('FUNCIONÁRIOS'!$E$4:$E$501,MATCH(B23,'FUNCIONÁRIOS'!$C$4:$C$501,0)),""))} -> NÃO | F23: 46160 | G23: =IF(H23<>"","✅ "&TEXT(H23,"HH:MM"),"→ Selecione a linha e use o menu ⏱️ Ponto") -> ✅ 08:14 | H23: 0.34305556 | I23: =IF(J23<>"","✅ "&TEXT(J23,"HH:MM"),"→ Selecione a linha e use o menu ⏱️ Ponto") -> ✅ 17:15 | J23: 0.71875 | K23: =IF(AND(H23<>"",J23<>""),J23-H23,"") -> 0.37569444 | L23: =IF(AND(H23<>"",J23=""),"🟢 No Evento",IF(AND(H23<>"",J23<>""),"✅ Finalizado",IF(B23<>"","⏳ Não entrou",""))) -> ✅ Finalizado
A24: =22 -> 22 | B24: Hananias Sousa Alves dos santos | C24: {=IF(B24="","",IFERROR(INDEX('FUNCIONÁRIOS'!$B$4:$B$501,MATCH(B24,'FUNCIONÁRIOS'!$C$4:$C$501,0)),""))} -> MONTE EVENTOS | D24: {=IF(B24="","",IFERROR(INDEX('FUNCIONÁRIOS'!$D$4:$D$501,MATCH(B24,'FUNCIONÁRIOS'!$C$4:$C$501,0)),""))} -> MONTADOR | E24: {=IF(B24="","",IFERROR(INDEX('FUNCIONÁRIOS'!$E$4:$E$501,MATCH(B24,'FUNCIONÁRIOS'!$C$4:$C$501,0)),""))} -> NÃO | F24: 46160 | G24: =IF(H24<>"","✅ "&TEXT(H24,"HH:MM"),"→ Selecione a linha e use o menu ⏱️ Ponto") -> ✅ 08:14 | H24: 0.34305556 | I24: =IF(J24<>"","✅ "&TEXT(J24,"HH:MM"),"→ Selecione a linha e use o menu ⏱️ Ponto") -> ✅ 17:15 | J24: 0.71875 | K24: =IF(AND(H24<>"",J24<>""),J24-H24,"") -> 0.37569444 | L24: =IF(AND(H24<>"",J24=""),"🟢 No Evento",IF(AND(H24<>"",J24<>""),"✅ Finalizado",IF(B24<>"","⏳ Não entrou",""))) -> ✅ Finalizado
A25: =23 -> 23 | B25: Erik natan Lopes Machado | C25: {=IF(B25="","",IFERROR(INDEX('FUNCIONÁRIOS'!$B$4:$B$501,MATCH(B25,'FUNCIONÁRIOS'!$C$4:$C$501,0)),""))} -> MONTE EVENTOS | D25: {=IF(B25="","",IFERROR(INDEX('FUNCIONÁRIOS'!$D$4:$D$501,MATCH(B25,'FUNCIONÁRIOS'!$C$4:$C$501,0)),""))} -> MONTADOR | E25: {=IF(B25="","",IFERROR(INDEX('FUNCIONÁRIOS'!$E$4:$E$501,MATCH(B25,'FUNCIONÁRIOS'!$C$4:$C$501,0)),""))} -> NÃO | F25: 46160 | G25: =IF(H25<>"","✅ "&TEXT(H25,"HH:MM"),"→ Selecione a linha e use o menu ⏱️ Ponto") -> ✅ 08:15 | H25: 0.34375 | I25: =IF(J25<>"","✅ "&TEXT(J25,"HH:MM"),"→ Selecione a linha e use o menu ⏱️ Ponto") -> ✅ 17:15 | J25: 0.71875 | K25: =IF(AND(H25<>"",J25<>""),J25-H25,"") -> 0.375 | L25: =IF(AND(H25<>"",J25=""),"🟢 No Evento",IF(AND(H25<>"",J25<>""),"✅ Finalizado",IF(B25<>"","⏳ Não entrou",""))) -> ✅ Finalizado
A26: =24 -> 24 | B26: Renato de Araújo Morais | C26: {=IF(B26="","",IFERROR(INDEX('FUNCIONÁRIOS'!$B$4:$B$501,MATCH(B26,'FUNCIONÁRIOS'!$C$4:$C$501,0)),""))} -> MONTE EVENTOS | D26: {=IF(B26="","",IFERROR(INDEX('FUNCIONÁRIOS'!$D$4:$D$501,MATCH(B26,'FUNCIONÁRIOS'!$C$4:$C$501,0)),""))} -> MONTADOR | E26: {=IF(B26="","",IFERROR(INDEX('FUNCIONÁRIOS'!$E$4:$E$501,MATCH(B26,'FUNCIONÁRIOS'!$C$4:$C$501,0)),""))} -> NÃO | F26: 46160 | G26: =IF(H26<>"","✅ "&TEXT(H26,"HH:MM"),"→ Selecione a linha e use o menu ⏱️ Ponto") -> ✅ 08:16 | H26: 0.34444444 | I26: =IF(J26<>"","✅ "&TEXT(J26,"HH:MM"),"→ Selecione a linha e use o menu ⏱️ Ponto") -> ✅ 17:14 | J26: 0.71805556 | K26: =IF(AND(H26<>"",J26<>""),J26-H26,"") -> 0.37361111 | L26: =IF(AND(H26<>"",J26=""),"🟢 No Evento",IF(AND(H26<>"",J26<>""),"✅ Finalizado",IF(B26<>"","⏳ Não entrou",""))) -> ✅ Finalizado
A27: =25 -> 25 | B27: Guilherme Silva dos Anjos | C27: {=IF(B27="","",IFERROR(INDEX('FUNCIONÁRIOS'!$B$4:$B$501,MATCH(B27,'FUNCIONÁRIOS'!$C$4:$C$501,0)),""))} -> MONTE EVENTOS | D27: {=IF(B27="","",IFERROR(INDEX('FUNCIONÁRIOS'!$D$4:$D$501,MATCH(B27,'FUNCIONÁRIOS'!$C$4:$C$501,0)),""))} -> MONTADOR | E27: {=IF(B27="","",IFERROR(INDEX('FUNCIONÁRIOS'!$E$4:$E$501,MATCH(B27,'FUNCIONÁRIOS'!$C$4:$C$501,0)),""))} -> NÃO | F27: 46160 | G27: =IF(H27<>"","✅ "&TEXT(H27,"HH:MM"),"→ Selecione a linha e use o menu ⏱️ Ponto") -> ✅ 08:17 | H27: 0.34513889 | I27: =IF(J27<>"","✅ "&TEXT(J27,"HH:MM"),"→ Selecione a linha e use o menu ⏱️ Ponto") -> ✅ 17:14 | J27: 0.71805556 | K27: =IF(AND(H27<>"",J27<>""),J27-H27,"") -> 0.37291667 | L27: =IF(AND(H27<>"",J27=""),"🟢 No Evento",IF(AND(H27<>"",J27<>""),"✅ Finalizado",IF(B27<>"","⏳ Não entrou",""))) -> ✅ Finalizado
A28: =26 -> 26 | B28: Andressa Santana Dias | C28: {=IF(B28="","",IFERROR(INDEX('FUNCIONÁRIOS'!$B$4:$B$501,MATCH(B28,'FUNCIONÁRIOS'!$C$4:$C$501,0)),""))} -> TJ SERVIÇOS | D28: {=IF(B28="","",IFERROR(INDEX('FUNCIONÁRIOS'!$D$4:$D$501,MATCH(B28,'FUNCIONÁRIOS'!$C$4:$C$501,0)),""))} -> BRIGADISTA | E28: {=IF(B28="","",IFERROR(INDEX('FUNCIONÁRIOS'!$E$4:$E$501,MATCH(B28,'FUNCIONÁRIOS'!$C$4:$C$501,0)),""))} -> NÃO | F28: 46160 | G28: =IF(H28<>"","✅ "&TEXT(H28,"HH:MM"),"→ Selecione a linha e use o menu ⏱️ Ponto") -> ✅ 08:18 | H28: 0.34583333 | I28: =IF(J28<>"","✅ "&TEXT(J28,"HH:MM"),"→ Selecione a linha e use o menu ⏱️ Ponto") -> ✅ 17:37 | J28: 0.73402778 | K28: =IF(AND(H28<>"",J28<>""),J28-H28,"") -> 0.38819444 | L28: =IF(AND(H28<>"",J28=""),"🟢 No Evento",IF(AND(H28<>"",J28<>""),"✅ Finalizado",IF(B28<>"","⏳ Não entrou",""))) -> ✅ Finalizado
A29: =28 -> 28 | B29: Marília de Jesus honorato | C29: {=IF(B29="","",IFERROR(INDEX('FUNCIONÁRIOS'!$B$4:$B$501,MATCH(B29,'FUNCIONÁRIOS'!$C$4:$C$501,0)),""))} -> TJ SERVIÇOS | D29: {=IF(B29="","",IFERROR(INDEX('FUNCIONÁRIOS'!$D$4:$D$501,MATCH(B29,'FUNCIONÁRIOS'!$C$4:$C$501,0)),""))} -> BRIGADISTA | E29: {=IF(B29="","",IFERROR(INDEX('FUNCIONÁRIOS'!$E$4:$E$501,MATCH(B29,'FUNCIONÁRIOS'!$C$4:$C$501,0)),""))} -> NÃO | F29: 46160 | G29: =IF(H29<>"","✅ "&TEXT(H29,"HH:MM"),"→ Selecione a linha e use o menu ⏱️ Ponto") -> ✅ 08:20 | H29: 0.34722222 | I29: =IF(J29<>"","✅ "&TEXT(J29,"HH:MM"),"→ Selecione a linha e use o menu ⏱️ Ponto") -> ✅ 17:37 | J29: 0.73402778 | K29: =IF(AND(H29<>"",J29<>""),J29-H29,"") -> 0.38680556 | L29: =IF(AND(H29<>"",J29=""),"🟢 No Evento",IF(AND(H29<>"",J29<>""),"✅ Finalizado",IF(B29<>"","⏳ Não entrou",""))) -> ✅ Finalizado
A30: =29 -> 29 | B30: Edna Maria da Silva Olívia | C30: {=IF(B30="","",IFERROR(INDEX('FUNCIONÁRIOS'!$B$4:$B$501,MATCH(B30,'FUNCIONÁRIOS'!$C$4:$C$501,0)),""))} -> FLASH MED | D30: ENFERMEIRA | E30: {=IF(B30="","",IFERROR(INDEX('FUNCIONÁRIOS'!$E$4:$E$501,MATCH(B30,'FUNCIONÁRIOS'!$C$4:$C$501,0)),""))} -> NÃO | F30: 46160 | G30: =IF(H30<>"","✅ "&TEXT(H30,"HH:MM"),"→ Selecione a linha e use o menu ⏱️ Ponto") -> ✅ 08:21 | H30: 0.34791667 | I30: =IF(J30<>"","✅ "&TEXT(J30,"HH:MM"),"→ Selecione a linha e use o menu ⏱️ Ponto") -> ✅ 17:40 | J30: 0.73611111 | K30: =IF(AND(H30<>"",J30<>""),J30-H30,"") -> 0.38819444 | L30: =IF(AND(H30<>"",J30=""),"🟢 No Evento",IF(AND(H30<>"",J30<>""),"✅ Finalizado",IF(B30<>"","⏳ Não entrou",""))) -> ✅ Finalizado
A31: =30 -> 30 | B31: Ricardo Souza dos santos | C31: {=IF(B31="","",IFERROR(INDEX('FUNCIONÁRIOS'!$B$4:$B$501,MATCH(B31,'FUNCIONÁRIOS'!$C$4:$C$501,0)),""))} -> FLASH MED | D31: {=IF(B31="","",IFERROR(INDEX('FUNCIONÁRIOS'!$D$4:$D$501,MATCH(B31,'FUNCIONÁRIOS'!$C$4:$C$501,0)),""))} -> SOCORRITA | E31: {=IF(B31="","",IFERROR(INDEX('FUNCIONÁRIOS'!$E$4:$E$501,MATCH(B31,'FUNCIONÁRIOS'!$C$4:$C$501,0)),""))} -> NÃO | F31: 46160 | G31: =IF(H31<>"","✅ "&TEXT(H31,"HH:MM"),"→ Selecione a linha e use o menu ⏱️ Ponto") -> ✅ 08:21 | H31: 0.34791667 | I31: =IF(J31<>"","✅ "&TEXT(J31,"HH:MM"),"→ Selecione a linha e use o menu ⏱️ Ponto") -> ✅ 17:40 | J31: 0.73611111 | K31: =IF(AND(H31<>"",J31<>""),J31-H31,"") -> 0.38819444 | L31: =IF(AND(H31<>"",J31=""),"🟢 No Evento",IF(AND(H31<>"",J31<>""),"✅ Finalizado",IF(B31<>"","⏳ Não entrou",""))) -> ✅ Finalizado
A32: =31 -> 31 | B32: Vinicius Monteiro Silva | C32: {=IF(B32="","",IFERROR(INDEX('FUNCIONÁRIOS'!$B$4:$B$501,MATCH(B32,'FUNCIONÁRIOS'!$C$4:$C$501,0)),""))} -> BIGODE | D32: {=IF(B32="","",IFERROR(INDEX('FUNCIONÁRIOS'!$D$4:$D$501,MATCH(B32,'FUNCIONÁRIOS'!$C$4:$C$501,0)),""))} -> CONTROLE DE ACESSO | E32: {=IF(B32="","",IFERROR(INDEX('FUNCIONÁRIOS'!$E$4:$E$501,MATCH(B32,'FUNCIONÁRIOS'!$C$4:$C$501,0)),""))} -> NÃO | F32: 46160 | G32: =IF(H32<>"","✅ "&TEXT(H32,"HH:MM"),"→ Selecione a linha e use o menu ⏱️ Ponto") -> ✅ 10:30 | H32: 0.4375 | I32: =IF(J32<>"","✅ "&TEXT(J32,"HH:MM"),"→ Selecione a linha e use o menu ⏱️ Ponto") -> ✅ 17:24 | J32: 0.725 | K32: =IF(AND(H32<>"",J32<>""),J32-H32,"") -> 0.2875 | L32: =IF(AND(H32<>"",J32=""),"🟢 No Evento",IF(AND(H32<>"",J32<>""),"✅ Finalizado",IF(B32<>"","⏳ Não entrou",""))) -> ✅ Finalizado
A33: =32 -> 32 | B33: Ronara Moreira Borges Meireles | C33: {=IF(B33="","",IFERROR(INDEX('FUNCIONÁRIOS'!$B$4:$B$501,MATCH(B33,'FUNCIONÁRIOS'!$C$4:$C$501,0)),""))} -> BIGODE | D33: {=IF(B33="","",IFERROR(INDEX('FUNCIONÁRIOS'!$D$4:$D$501,MATCH(B33,'FUNCIONÁRIOS'!$C$4:$C$501,0)),""))} -> CONTROLE DE ACESSO | E33: {=IF(B33="","",IFERROR(INDEX('FUNCIONÁRIOS'!$E$4:$E$501,MATCH(B33,'FUNCIONÁRIOS'!$C$4:$C$501,0)),""))} -> NÃO | F33: 46160 | G33: =IF(H33<>"","✅ "&TEXT(H33,"HH:MM"),"→ Selecione a linha e use o menu ⏱️ Ponto") -> ✅ 10:30 | H33: 0.4375 | I33: =IF(J33<>"","✅ "&TEXT(J33,"HH:MM"),"→ Selecione a linha e use o menu ⏱️ Ponto") -> ✅ 17:24 | J33: 0.725 | K33: =IF(AND(H33<>"",J33<>""),J33-H33,"") -> 0.2875 | L33: =IF(AND(H33<>"",J33=""),"🟢 No Evento",IF(AND(H33<>"",J33<>""),"✅ Finalizado",IF(B33<>"","⏳ Não entrou",""))) -> ✅ Finalizado
A34: =33 -> 33 | B34: Wagner Martins lira | C34: {=IF(B34="","",IFERROR(INDEX('FUNCIONÁRIOS'!$B$4:$B$501,MATCH(B34,'FUNCIONÁRIOS'!$C$4:$C$501,0)),""))} -> YES | D34: {=IF(B34="","",IFERROR(INDEX('FUNCIONÁRIOS'!$D$4:$D$501,MATCH(B34,'FUNCIONÁRIOS'!$C$4:$C$501,0)),""))} -> TEC SEGURANÇA | E34: {=IF(B34="","",IFERROR(INDEX('FUNCIONÁRIOS'!$E$4:$E$501,MATCH(B34,'FUNCIONÁRIOS'!$C$4:$C$501,0)),""))} -> NÃO | F34: 46160 | G34: =IF(H34<>"","✅ "&TEXT(H34,"HH:MM"),"→ Selecione a linha e use o menu ⏱️ Ponto") -> ✅ 11:00 | H34: 0.45833333 | I34: =IF(J34<>"","✅ "&TEXT(J34,"HH:MM"),"→ Selecione a linha e use o menu ⏱️ Ponto") -> ✅ 17:22 | J34: 0.72361111 | K34: =IF(AND(H34<>"",J34<>""),J34-H34,"") -> 0.26527778 | L34: =IF(AND(H34<>"",J34=""),"🟢 No Evento",IF(AND(H34<>"",J34<>""),"✅ Finalizado",IF(B34<>"","⏳ Não entrou",""))) -> ✅ Finalizado
A36: =34 -> 34 | B36: vinicius Gomes silva | C36: YES | D36: {=IF(B36="","",IFERROR(INDEX('FUNCIONÁRIOS'!$D$4:$D$501,MATCH(B36,'FUNCIONÁRIOS'!$C$4:$C$501,0)),""))} -> TEC SEGURANÇA | E36: {=IF(B36="","",IFERROR(INDEX('FUNCIONÁRIOS'!$E$4:$E$501,MATCH(B36,'FUNCIONÁRIOS'!$C$4:$C$501,0)),""))} -> NÃO | F36: 46161 | G36: =IF(H36<>"","✅ "&TEXT(H36,"HH:MM"),"→ Selecione a linha e use o menu ⏱️ Ponto") -> ✅ 08:53 | H36: 08:53 | I36: =IF(J36<>"","✅ "&TEXT(J36,"HH:MM"),"→ Selecione a linha e use o menu ⏱️ Ponto") -> ✅ 12:00 | J36: 0.5 | L36: =IF(AND(H36<>"",J36=""),"🟢 No Evento",IF(AND(H36<>"",J36<>""),"✅ Finalizado",IF(B36<>"","⏳ Não entrou",""))) -> ✅ Finalizado
A37: =35 -> 35 | B37: KLEBIO DOS REIS SILVA | C37: - | D37: {=IF(B37="","",IFERROR(INDEX('FUNCIONÁRIOS'!$D$4:$D$501,MATCH(B37,'FUNCIONÁRIOS'!$C$4:$C$501,0)),""))} -> OPERADOR DE EMPILHADEIRA | E37: {=IF(B37="","",IFERROR(INDEX('FUNCIONÁRIOS'!$E$4:$E$501,MATCH(B37,'FUNCIONÁRIOS'!$C$4:$C$501,0)),""))} -> NÃO | F37: 46161 | G37: =IF(H37<>"","✅ "&TEXT(H37,"HH:MM"),"→ Selecione a linha e use o menu ⏱️ Ponto") -> ✅ 08:00 | H37: 0.33333333 | I37: =IF(J37<>"","✅ "&TEXT(J37,"HH:MM"),"→ Selecione a linha e use o menu ⏱️ Ponto") -> ✅ 17:50 | J37: 0.74305556 | K37: =IF(AND(H37<>"",J37<>""),J37-H37,"") -> 0.40972222 | L37: =IF(AND(H37<>"",J37=""),"🟢 No Evento",IF(AND(H37<>"",J37<>""),"✅ Finalizado",IF(B37<>"","⏳ Não entrou",""))) -> ✅ Finalizado
A38: =36 -> 36 | B38: Juan Miguel | C38: {=IF(B38="","",IFERROR(INDEX('FUNCIONÁRIOS'!$B$4:$B$501,MATCH(B38,'FUNCIONÁRIOS'!$C$4:$C$501,0)),""))} -> MONTE EVENTOS | D38: {=IF(B38="","",IFERROR(INDEX('FUNCIONÁRIOS'!$D$4:$D$501,MATCH(B38,'FUNCIONÁRIOS'!$C$4:$C$501,0)),""))} -> MONTADOR | E38: {=IF(B38="","",IFERROR(INDEX('FUNCIONÁRIOS'!$E$4:$E$501,MATCH(B38,'FUNCIONÁRIOS'!$C$4:$C$501,0)),""))} -> NÃO | F38: 46161 | G38: =IF(H38<>"","✅ "&TEXT(H38,"HH:MM"),"→ Selecione a linha e use o menu ⏱️ Ponto") -> ✅ 08:00 | H38: 0.33333333 | I38: =IF(J38<>"","✅ "&TEXT(J38,"HH:MM"),"→ Selecione a linha e use o menu ⏱️ Ponto") -> ✅ 18:00 | J38: 0.75 | K38: =IF(AND(H38<>"",J38<>""),J38-H38,"") -> 0.41666667 | L38: =IF(AND(H38<>"",J38=""),"🟢 No Evento",IF(AND(H38<>"",J38<>""),"✅ Finalizado",IF(B38<>"","⏳ Não entrou",""))) -> ✅ Finalizado
A39: =37 -> 37 | B39: Wagner Martins lira | C39: {=IF(B39="","",IFERROR(INDEX('FUNCIONÁRIOS'!$B$4:$B$501,MATCH(B39,'FUNCIONÁRIOS'!$C$4:$C$501,0)),""))} -> YES | D39: {=IF(B39="","",IFERROR(INDEX('FUNCIONÁRIOS'!$D$4:$D$501,MATCH(B39,'FUNCIONÁRIOS'!$C$4:$C$501,0)),""))} -> TEC SEGURANÇA | E39: {=IF(B39="","",IFERROR(INDEX('FUNCIONÁRIOS'!$E$4:$E$501,MATCH(B39,'FUNCIONÁRIOS'!$C$4:$C$501,0)),""))} -> NÃO | F39: 46161 | G39: =IF(H39<>"","✅ "&TEXT(H39,"HH:MM"),"→ Selecione a linha e use o menu ⏱️ Ponto") -> ✅ 08:00 | H39: 0.33333333 | I39: =IF(J39<>"","✅ "&TEXT(J39,"HH:MM"),"→ Selecione a linha e use o menu ⏱️ Ponto") -> ✅ 16:44 | J39: 0.69722222 | K39: =IF(AND(H39<>"",J39<>""),J39-H39,"") -> 0.36388889 | L39: =IF(AND(H39<>"",J39=""),"🟢 No Evento",IF(AND(H39<>"",J39<>""),"✅ Finalizado",IF(B39<>"","⏳ Não entrou",""))) -> ✅ Finalizado
A40: =38 -> 38 | B40: Andressa Santana Dias | C40: {=IF(B40="","",IFERROR(INDEX('FUNCIONÁRIOS'!$B$4:$B$501,MATCH(B40,'FUNCIONÁRIOS'!$C$4:$C$501,0)),""))} -> TJ SERVIÇOS | D40: {=IF(B40="","",IFERROR(INDEX('FUNCIONÁRIOS'!$D$4:$D$501,MATCH(B40,'FUNCIONÁRIOS'!$C$4:$C$501,0)),""))} -> BRIGADISTA | E40: {=IF(B40="","",IFERROR(INDEX('FUNCIONÁRIOS'!$E$4:$E$501,MATCH(B40,'FUNCIONÁRIOS'!$C$4:$C$501,0)),""))} -> NÃO | F40: 46161 | G40: =IF(H40<>"","✅ "&TEXT(H40,"HH:MM"),"→ Selecione a linha e use o menu ⏱️ Ponto") -> ✅ 08:00 | H40: 0.33333333 | I40: =IF(J40<>"","✅ "&TEXT(J40,"HH:MM"),"→ Selecione a linha e use o menu ⏱️ Ponto") -> ✅ 18:00 | J40: 0.75 | K40: =IF(AND(H40<>"",J40<>""),J40-H40,"") -> 0.41666667 | L40: =IF(AND(H40<>"",J40=""),"🟢 No Evento",IF(AND(H40<>"",J40<>""),"✅ Finalizado",IF(B40<>"","⏳ Não entrou",""))) -> ✅ Finalizado
A41: =39 -> 39 | B41: Andresa da Silva | C41: TJ SERVIÇOS | D41: {=IF(B41="","",IFERROR(INDEX('FUNCIONÁRIOS'!$D$4:$D$501,MATCH(B41,'FUNCIONÁRIOS'!$C$4:$C$501,0)),""))} -> BRIGADISTA | E41: {=IF(B41="","",IFERROR(INDEX('FUNCIONÁRIOS'!$E$4:$E$501,MATCH(B41,'FUNCIONÁRIOS'!$C$4:$C$501,0)),""))} -> NÃO | F41: 46161 | G41: =IF(H41<>"","✅ "&TEXT(H41,"HH:MM"),"→ Selecione a linha e use o menu ⏱️ Ponto") -> ✅ 08:00 | H41: 0.33333333 | I41: =IF(J41<>"","✅ "&TEXT(J41,"HH:MM"),"→ Selecione a linha e use o menu ⏱️ Ponto") -> ✅ 18:00 | J41: 0.75 | K41: =IF(AND(H41<>"",J41<>""),J41-H41,"") -> 0.41666667 | L41: =IF(AND(H41<>"",J41=""),"🟢 No Evento",IF(AND(H41<>"",J41<>""),"✅ Finalizado",IF(B41<>"","⏳ Não entrou",""))) -> ✅ Finalizado
A42: =40 -> 40 | B42: José Wellingtom | C42: {=IF(B42="","",IFERROR(INDEX('FUNCIONÁRIOS'!$B$4:$B$501,MATCH(B42,'FUNCIONÁRIOS'!$C$4:$C$501,0)),""))} -> MONTE EVENTOS | D42: {=IF(B42="","",IFERROR(INDEX('FUNCIONÁRIOS'!$D$4:$D$501,MATCH(B42,'FUNCIONÁRIOS'!$C$4:$C$501,0)),""))} -> MONTADOR | E42: {=IF(B42="","",IFERROR(INDEX('FUNCIONÁRIOS'!$E$4:$E$501,MATCH(B42,'FUNCIONÁRIOS'!$C$4:$C$501,0)),""))} -> NÃO | F42: 46161 | G42: =IF(H42<>"","✅ "&TEXT(H42,"HH:MM"),"→ Selecione a linha e use o menu ⏱️ Ponto") -> ✅ 08:00 | H42: 0.33333333 | I42: =IF(J42<>"","✅ "&TEXT(J42,"HH:MM"),"→ Selecione a linha e use o menu ⏱️ Ponto") -> ✅ 18:00 | J42: 0.75 | K42: =IF(AND(H42<>"",J42<>""),J42-H42,"") -> 0.41666667 | L42: =IF(AND(H42<>"",J42=""),"🟢 No Evento",IF(AND(H42<>"",J42<>""),"✅ Finalizado",IF(B42<>"","⏳ Não entrou",""))) -> ✅ Finalizado
...

Sheet 📊 Resumo Geral
A1: 📊 RESUMO GERAL DO EVENTO
A3: 📅 FILTRO POR DATA — Selecione a data na célula H3 para filtrar os indicadores | H3: DATA FILTRO (deixe vazio = todos): | I3: 📋 Datas disponíveis em Entrada e Saída:
H4: 46160 | I4: (Consulte coluna DATA em ⏱️ Entrada e Saída)
H5: ⬆️ Digite ou selecione a data
A7: 🔢 INDICADORES EM TEMPO REAL
A8: 🟢 DENTRO DO EVENTO AGORA | B8: ✅ FINALIZADOS | C8: ⏳ NÃO ENTRARAM | D8: 👥 TOTAL NO DIA | E8: ⭐ COORDENADORES | F8: 🏢 EMPRESAS
A9: =SUMPRODUCT(('⏱️ Entrada e Saída'!$B$4:$B$507<>"")*('⏱️ Entrada e Saída'!$H$4:$H$507<>"")*('⏱️ Entrada e Saída'!$J$4:$J$507="")*(IF($H$4="",1,TEXT('⏱️ Entrada e Saída'!$F$4:$F$507,"DD/MM")=TEXT($H$4,"DD/MM")))) -> 0 | B9: =SUMPRODUCT(('⏱️ Entrada e Saída'!$B$4:$B$507<>"")*('⏱️ Entrada e Saída'!$H$4:$H$507<>"")*('⏱️ Entrada e Saída'!$J$4:$J$507<>"")*(IF($H$4="",1,TEXT('⏱️ Entrada e Saída'!$F$4:$F$507,"DD/MM")=TEXT($H$4,"DD/MM")))) -> 31 | C9: =SUMPRODUCT(('⏱️ Entrada e Saída'!$B$4:$B$507<>"")*('⏱️ Entrada e Saída'!$H$4:$H$507="")*(IF($H$4="",1,TEXT('⏱️ Entrada e Saída'!$F$4:$F$507,"DD/MM")=TEXT($H$4,"DD/MM")))) -> 0 | D9: =SUMPRODUCT(('⏱️ Entrada e Saída'!$B$4:$B$507<>"")*(IF($H$4="",1,TEXT('⏱️ Entrada e Saída'!$F$4:$F$507,"DD/MM")=TEXT($H$4,"DD/MM")))) -> 31 | E9: =SUMPRODUCT(('⏱️ Entrada e Saída'!$E$4:$E$507="SIM")*(IF($H$4="",1,TEXT('⏱️ Entrada e Saída'!$F$4:$F$507,"DD/MM")=TEXT($H$4,"DD/MM")))) -> 2 | F9: =COUNTA('📋 Empresas'!$B$4:$B$103) -> 68
A12: ⏱️ HORAS TRABALHADAS NO DIA FILTRADO
A13: TOTAL DE HORAS
A14: =SUMPRODUCT((IF($H$4="",1,TEXT('⏱️ Entrada e Saída'!$F$4:$F$507,"DD/MM")=TEXT($H$4,"DD/MM")))*(IF(ISNUMBER('⏱️ Entrada e Saída'!$K$4:$K$507),'⏱️ Entrada e Saída'!$K$4:$K$507,0))) -> 11.434028
A16: 🏢 FUNCIONÁRIOS POR EMPRESA (DIA FILTRADO)
A17: EMPRESA | B17: TOTAL | C17: NO EVENTO | D17: FINALIZADOS | E17: NÃO ENTRARAM | F17: % PRESENÇA | G17: HORAS TRABALHADAS
A18: ='📋 Empresas'!B4 -> PONCIANO SOLUÇÕES | B18: =IF(OR(A18="",A18=0),"",SUMPRODUCT(('⏱️ Entrada e Saída'!$C$4:$C$507=A18)*IF($H$4="",1,TEXT('⏱️ Entrada e Saída'!$F$4:$F$507,"DD/MM")=TEXT($H$4,"DD/MM")))) -> 1 | C18: =IF(OR(A18="",A18=0),"",SUMPRODUCT(('⏱️ Entrada e Saída'!$C$4:$C$507=A18)*('⏱️ Entrada e Saída'!$H$4:$H$507<>"")*('⏱️ Entrada e Saída'!$J$4:$J$507="")*IF($H$4="",1,TEXT('⏱️ Entrada e Saída'!$F$4:$F$507,"DD/MM")=TEXT($H$4,"DD/MM")))) -> 0 | D18: =IF(OR(A18="",A18=0),"",SUMPRODUCT(('⏱️ Entrada e Saída'!$C$4:$C$507=A18)*('⏱️ Entrada e Saída'!$H$4:$H$507<>"")*('⏱️ Entrada e Saída'!$J$4:$J$507<>"")*IF($H$4="",1,TEXT('⏱️ Entrada e Saída'!$F$4:$F$507,"DD/MM")=TEXT($H$4,"DD/MM")))) -> 1 | E18: =IF(OR(A18="",A18=0,B18=""),"",B18-C18-D18) -> 0 | F18: =IF(OR(A18="",A18=0,B18=0,B18=""),"",(C18+D18)/B18) -> 1 | G18: =IF(OR(A18="",A18=0),"",SUMPRODUCT(('⏱️ Entrada e Saída'!$C$4:$C$507=A18)*('⏱️ Entrada e Saída'!$L$4:$L$507="✅ Finalizado")*IF($H$4="",1,TEXT('⏱️ Entrada e Saída'!$F$4:$F$507,"dd/mm")=TEXT($H$4,"dd/mm"))*IFERROR(VALUE('⏱️ Entrada e Saída'!$K$4:$K$507),0))) -> 0.42569444
A19: ='📋 Empresas'!B5 -> MONTE EVENTOS | B19: =IF(OR(A19="",A19=0),"",SUMPRODUCT(('⏱️ Entrada e Saída'!$C$4:$C$507=A19)*IF($H$4="",1,TEXT('⏱️ Entrada e Saída'!$F$4:$F$507,"DD/MM")=TEXT($H$4,"DD/MM")))) -> 20 | C19: =IF(OR(A19="",A19=0),"",SUMPRODUCT(('⏱️ Entrada e Saída'!$C$4:$C$507=A19)*('⏱️ Entrada e Saída'!$H$4:$H$507<>"")*('⏱️ Entrada e Saída'!$J$4:$J$507="")*IF($H$4="",1,TEXT('⏱️ Entrada e Saída'!$F$4:$F$507,"DD/MM")=TEXT($H$4,"DD/MM")))) -> 0 | D19: =IF(OR(A19="",A19=0),"",SUMPRODUCT(('⏱️ Entrada e Saída'!$C$4:$C$507=A19)*('⏱️ Entrada e Saída'!$H$4:$H$507<>"")*('⏱️ Entrada e Saída'!$J$4:$J$507<>"")*IF($H$4="",1,TEXT('⏱️ Entrada e Saída'!$F$4:$F$507,"DD/MM")=TEXT($H$4,"DD/MM")))) -> 20 | E19: =IF(OR(A19="",A19=0,B19=""),"",B19-C19-D19) -> 0 | F19: =IF(OR(A19="",A19=0,B19=0,B19=""),"",(C19+D19)/B19) -> 1 | G19: =IF(OR(A19="",A19=0),"",SUMPRODUCT(('⏱️ Entrada e Saída'!$C$4:$C$507=A19)*('⏱️ Entrada e Saída'!$L$4:$L$507="✅ Finalizado")*IF($H$4="",1,TEXT('⏱️ Entrada e Saída'!$F$4:$F$507,"dd/mm")=TEXT($H$4,"dd/mm"))*IFERROR(VALUE('⏱️ Entrada e Saída'!$K$4:$K$507),0))) -> 7.6041667
A20: ='📋 Empresas'!B6 -> UP MUSIC | B20: =IF(OR(A20="",A20=0),"",SUMPRODUCT(('⏱️ Entrada e Saída'!$C$4:$C$507=A20)*IF($H$4="",1,TEXT('⏱️ Entrada e Saída'!$F$4:$F$507,"DD/MM")=TEXT($H$4,"DD/MM")))) -> 0 | C20: =IF(OR(A20="",A20=0),"",SUMPRODUCT(('⏱️ Entrada e Saída'!$C$4:$C$507=A20)*('⏱️ Entrada e Saída'!$H$4:$H$507<>"")*('⏱️ Entrada e Saída'!$J$4:$J$507="")*IF($H$4="",1,TEXT('⏱️ Entrada e Saída'!$F$4:$F$507,"DD/MM")=TEXT($H$4,"DD/MM")))) -> 0 | D20: =IF(OR(A20="",A20=0),"",SUMPRODUCT(('⏱️ Entrada e Saída'!$C$4:$C$507=A20)*('⏱️ Entrada e Saída'!$H$4:$H$507<>"")*('⏱️ Entrada e Saída'!$J$4:$J$507<>"")*IF($H$4="",1,TEXT('⏱️ Entrada e Saída'!$F$4:$F$507,"DD/MM")=TEXT($H$4,"DD/MM")))) -> 0 | E20: =IF(OR(A20="",A20=0,B20=""),"",B20-C20-D20) -> 0 | F20: =IF(OR(A20="",A20=0,B20=0,B20=""),"",(C20+D20)/B20) | G20: =IF(OR(A20="",A20=0),"",SUMPRODUCT(('⏱️ Entrada e Saída'!$C$4:$C$507=A20)*('⏱️ Entrada e Saída'!$L$4:$L$507="✅ Finalizado")*IF($H$4="",1,TEXT('⏱️ Entrada e Saída'!$F$4:$F$507,"dd/mm")=TEXT($H$4,"dd/mm"))*IFERROR(VALUE('⏱️ Entrada e Saída'!$K$4:$K$507),0))) -> 0
A21: ='📋 Empresas'!B7 -> TJ SERVIÇOS | B21: =IF(OR(A21="",A21=0),"",SUMPRODUCT(('⏱️ Entrada e Saída'!$C$4:$C$507=A21)*IF($H$4="",1,TEXT('⏱️ Entrada e Saída'!$F$4:$F$507,"DD/MM")=TEXT($H$4,"DD/MM")))) -> 3 | C21: =IF(OR(A21="",A21=0),"",SUMPRODUCT(('⏱️ Entrada e Saída'!$C$4:$C$507=A21)*('⏱️ Entrada e Saída'!$H$4:$H$507<>"")*('⏱️ Entrada e Saída'!$J$4:$J$507="")*IF($H$4="",1,TEXT('⏱️ Entrada e Saída'!$F$4:$F$507,"DD/MM")=TEXT($H$4,"DD/MM")))) -> 0 | D21: =IF(OR(A21="",A21=0),"",SUMPRODUCT(('⏱️ Entrada e Saída'!$C$4:$C$507=A21)*('⏱️ Entrada e Saída'!$H$4:$H$507<>"")*('⏱️ Entrada e Saída'!$J$4:$J$507<>"")*IF($H$4="",1,TEXT('⏱️ Entrada e Saída'!$F$4:$F$507,"DD/MM")=TEXT($H$4,"DD/MM")))) -> 3 | E21: =IF(OR(A21="",A21=0,B21=""),"",B21-C21-D21) -> 0 | F21: =IF(OR(A21="",A21=0,B21=0,B21=""),"",(C21+D21)/B21) -> 1 | G21: =IF(OR(A21="",A21=0),"",SUMPRODUCT(('⏱️ Entrada e Saída'!$C$4:$C$507=A21)*('⏱️ Entrada e Saída'!$L$4:$L$507="✅ Finalizado")*IF($H$4="",1,TEXT('⏱️ Entrada e Saída'!$F$4:$F$507,"dd/mm")=TEXT($H$4,"dd/mm"))*IFERROR(VALUE('⏱️ Entrada e Saída'!$K$4:$K$507),0))) -> 1.1298611
A22: ='📋 Empresas'!B8 -> FLASH MED | B22: =IF(OR(A22="",A22=0),"",SUMPRODUCT(('⏱️ Entrada e Saída'!$C$4:$C$507=A22)*IF($H$4="",1,TEXT('⏱️ Entrada e Saída'!$F$4:$F$507,"DD/MM")=TEXT($H$4,"DD/MM")))) -> 2 | C22: =IF(OR(A22="",A22=0),"",SUMPRODUCT(('⏱️ Entrada e Saída'!$C$4:$C$507=A22)*('⏱️ Entrada e Saída'!$H$4:$H$507<>"")*('⏱️ Entrada e Saída'!$J$4:$J$507="")*IF($H$4="",1,TEXT('⏱️ Entrada e Saída'!$F$4:$F$507,"DD/MM")=TEXT($H$4,"DD/MM")))) -> 0 | D22: =IF(OR(A22="",A22=0),"",SUMPRODUCT(('⏱️ Entrada e Saída'!$C$4:$C$507=A22)*('⏱️ Entrada e Saída'!$H$4:$H$507<>"")*('⏱️ Entrada e Saída'!$J$4:$J$507<>"")*IF($H$4="",1,TEXT('⏱️ Entrada e Saída'!$F$4:$F$507,"DD/MM")=TEXT($H$4,"DD/MM")))) -> 2 | E22: =IF(OR(A22="",A22=0,B22=""),"",B22-C22-D22) -> 0 | F22: =IF(OR(A22="",A22=0,B22=0,B22=""),"",(C22+D22)/B22) -> 1 | G22: =IF(OR(A22="",A22=0),"",SUMPRODUCT(('⏱️ Entrada e Saída'!$C$4:$C$507=A22)*('⏱️ Entrada e Saída'!$L$4:$L$507="✅ Finalizado")*IF($H$4="",1,TEXT('⏱️ Entrada e Saída'!$F$4:$F$507,"dd/mm")=TEXT($H$4,"dd/mm"))*IFERROR(VALUE('⏱️ Entrada e Saída'!$K$4:$K$507),0))) -> 0.77638889
A23: ='📋 Empresas'!B9 -> YES | B23: =IF(OR(A23="",A23=0),"",SUMPRODUCT(('⏱️ Entrada e Saída'!$C$4:$C$507=A23)*IF($H$4="",1,TEXT('⏱️ Entrada e Saída'!$F$4:$F$507,"DD/MM")=TEXT($H$4,"DD/MM")))) -> 1 | C23: =IF(OR(A23="",A23=0),"",SUMPRODUCT(('⏱️ Entrada e Saída'!$C$4:$C$507=A23)*('⏱️ Entrada e Saída'!$H$4:$H$507<>"")*('⏱️ Entrada e Saída'!$J$4:$J$507="")*IF($H$4="",1,TEXT('⏱️ Entrada e Saída'!$F$4:$F$507,"DD/MM")=TEXT($H$4,"DD/MM")))) -> 0 | D23: =IF(OR(A23="",A23=0),"",SUMPRODUCT(('⏱️ Entrada e Saída'!$C$4:$C$507=A23)*('⏱️ Entrada e Saída'!$H$4:$H$507<>"")*('⏱️ Entrada e Saída'!$J$4:$J$507<>"")*IF($H$4="",1,TEXT('⏱️ Entrada e Saída'!$F$4:$F$507,"DD/MM")=TEXT($H$4,"DD/MM")))) -> 1 | E23: =IF(OR(A23="",A23=0,B23=""),"",B23-C23-D23) -> 0 | F23: =IF(OR(A23="",A23=0,B23=0,B23=""),"",(C23+D23)/B23) -> 1 | G23: =IF(OR(A23="",A23=0),"",SUMPRODUCT(('⏱️ Entrada e Saída'!$C$4:$C$507=A23)*('⏱️ Entrada e Saída'!$L$4:$L$507="✅ Finalizado")*IF($H$4="",1,TEXT('⏱️ Entrada e Saída'!$F$4:$F$507,"dd/mm")=TEXT($H$4,"dd/mm"))*IFERROR(VALUE('⏱️ Entrada e Saída'!$K$4:$K$507),0))) -> 0.26527778
A24: ='📋 Empresas'!B10 -> BIGODE | B24: =IF(OR(A24="",A24=0),"",SUMPRODUCT(('⏱️ Entrada e Saída'!$C$4:$C$507=A24)*IF($H$4="",1,TEXT('⏱️ Entrada e Saída'!$F$4:$F$507,"DD/MM")=TEXT($H$4,"DD/MM")))) -> 2 | C24: =IF(OR(A24="",A24=0),"",SUMPRODUCT(('⏱️ Entrada e Saída'!$C$4:$C$507=A24)*('⏱️ Entrada e Saída'!$H$4:$H$507<>"")*('⏱️ Entrada e Saída'!$J$4:$J$507="")*IF($H$4="",1,TEXT('⏱️ Entrada e Saída'!$F$4:$F$507,"DD/MM")=TEXT($H$4,"DD/MM")))) -> 0 | D24: =IF(OR(A24="",A24=0),"",SUMPRODUCT(('⏱️ Entrada e Saída'!$C$4:$C$507=A24)*('⏱️ Entrada e Saída'!$H$4:$H$507<>"")*('⏱️ Entrada e Saída'!$J$4:$J$507<>"")*IF($H$4="",1,TEXT('⏱️ Entrada e Saída'!$F$4:$F$507,"DD/MM")=TEXT($H$4,"DD/MM")))) -> 2 | E24: =IF(OR(A24="",A24=0,B24=""),"",B24-C24-D24) -> 0 | F24: =IF(OR(A24="",A24=0,B24=0,B24=""),"",(C24+D24)/B24) -> 1 | G24: =IF(OR(A24="",A24=0),"",SUMPRODUCT(('⏱️ Entrada e Saída'!$C$4:$C$507=A24)*('⏱️ Entrada e Saída'!$L$4:$L$507="✅ Finalizado")*IF($H$4="",1,TEXT('⏱️ Entrada e Saída'!$F$4:$F$507,"dd/mm")=TEXT($H$4,"dd/mm"))*IFERROR(VALUE('⏱️ Entrada e Saída'!$K$4:$K$507),0))) -> 0.575
A25: ='📋 Empresas'!B11 -> NLEDS LOCAÇÃO - PAINEIS DE LED | B25: =IF(OR(A25="",A25=0),"",SUMPRODUCT(('⏱️ Entrada e Saída'!$C$4:$C$507=A25)*IF($H$4="",1,TEXT('⏱️ Entrada e Saída'!$F$4:$F$507,"DD/MM")=TEXT($H$4,"DD/MM")))) -> 0 | C25: =IF(OR(A25="",A25=0),"",SUMPRODUCT(('⏱️ Entrada e Saída'!$C$4:$C$507=A25)*('⏱️ Entrada e Saída'!$H$4:$H$507<>"")*('⏱️ Entrada e Saída'!$J$4:$J$507="")*IF($H$4="",1,TEXT('⏱️ Entrada e Saída'!$F$4:$F$507,"DD/MM")=TEXT($H$4,"DD/MM")))) -> 0 | D25: =IF(OR(A25="",A25=0),"",SUMPRODUCT(('⏱️ Entrada e Saída'!$C$4:$C$507=A25)*('⏱️ Entrada e Saída'!$H$4:$H$507<>"")*('⏱️ Entrada e Saída'!$J$4:$J$507<>"")*IF($H$4="",1,TEXT('⏱️ Entrada e Saída'!$F$4:$F$507,"DD/MM")=TEXT($H$4,"DD/MM")))) -> 0 | E25: =IF(OR(A25="",A25=0,B25=""),"",B25-C25-D25) -> 0 | F25: =IF(OR(A25="",A25=0,B25=0,B25=""),"",(C25+D25)/B25) | G25: =IF(OR(A25="",A25=0),"",SUMPRODUCT(('⏱️ Entrada e Saída'!$C$4:$C$507=A25)*('⏱️ Entrada e Saída'!$L$4:$L$507="✅ Finalizado")*IF($H$4="",1,TEXT('⏱️ Entrada e Saída'!$F$4:$F$507,"dd/mm")=TEXT($H$4,"dd/mm"))*IFERROR(VALUE('⏱️ Entrada e Saída'!$K$4:$K$507),0))) -> 0
A26: ='📋 Empresas'!B12 -> ASSOCIAÇÃO ASSUNÇÃO | B26: =IF(OR(A26="",A26=0),"",SUMPRODUCT(('⏱️ Entrada e Saída'!$C$4:$C$507=A26)*IF($H$4="",1,TEXT('⏱️ Entrada e Saída'!$F$4:$F$507,"DD/MM")=TEXT($H$4,"DD/MM")))) -> 0 | C26: =IF(OR(A26="",A26=0),"",SUMPRODUCT(('⏱️ Entrada e Saída'!$C$4:$C$507=A26)*('⏱️ Entrada e Saída'!$H$4:$H$507<>"")*('⏱️ Entrada e Saída'!$J$4:$J$507="")*IF($H$4="",1,TEXT('⏱️ Entrada e Saída'!$F$4:$F$507,"DD/MM")=TEXT($H$4,"DD/MM")))) -> 0 | D26: =IF(OR(A26="",A26=0),"",SUMPRODUCT(('⏱️ Entrada e Saída'!$C$4:$C$507=A26)*('⏱️ Entrada e Saída'!$H$4:$H$507<>"")*('⏱️ Entrada e Saída'!$J$4:$J$507<>"")*IF($H$4="",1,TEXT('⏱️ Entrada e Saída'!$F$4:$F$507,"DD/MM")=TEXT($H$4,"DD/MM")))) -> 0 | E26: =IF(OR(A26="",A26=0,B26=""),"",B26-C26-D26) -> 0 | F26: =IF(OR(A26="",A26=0,B26=0,B26=""),"",(C26+D26)/B26) | G26: =IF(OR(A26="",A26=0),"",SUMPRODUCT(('⏱️ Entrada e Saída'!$C$4:$C$507=A26)*('⏱️ Entrada e Saída'!$L$4:$L$507="✅ Finalizado")*IF($H$4="",1,TEXT('⏱️ Entrada e Saída'!$F$4:$F$507,"dd/mm")=TEXT($H$4,"dd/mm"))*IFERROR(VALUE('⏱️ Entrada e Saída'!$K$4:$K$507),0))) -> 0
A27: ='📋 Empresas'!B13 -> FABINHO EVENTOS | B27: =IF(OR(A27="",A27=0),"",SUMPRODUCT(('⏱️ Entrada e Saída'!$C$4:$C$507=A27)*IF($H$4="",1,TEXT('⏱️ Entrada e Saída'!$F$4:$F$507,"DD/MM")=TEXT($H$4,"DD/MM")))) -> 0 | C27: =IF(OR(A27="",A27=0),"",SUMPRODUCT(('⏱️ Entrada e Saída'!$C$4:$C$507=A27)*('⏱️ Entrada e Saída'!$H$4:$H$507<>"")*('⏱️ Entrada e Saída'!$J$4:$J$507="")*IF($H$4="",1,TEXT('⏱️ Entrada e Saída'!$F$4:$F$507,"DD/MM")=TEXT($H$4,"DD/MM")))) -> 0 | D27: =IF(OR(A27="",A27=0),"",SUMPRODUCT(('⏱️ Entrada e Saída'!$C$4:$C$507=A27)*('⏱️ Entrada e Saída'!$H$4:$H$507<>"")*('⏱️ Entrada e Saída'!$J$4:$J$507<>"")*IF($H$4="",1,TEXT('⏱️ Entrada e Saída'!$F$4:$F$507,"DD/MM")=TEXT($H$4,"DD/MM")))) -> 0 | E27: =IF(OR(A27="",A27=0,B27=""),"",B27-C27-D27) -> 0 | F27: =IF(OR(A27="",A27=0,B27=0,B27=""),"",(C27+D27)/B27) | G27: =IF(OR(A27="",A27=0),"",SUMPRODUCT(('⏱️ Entrada e Saída'!$C$4:$C$507=A27)*('⏱️ Entrada e Saída'!$L$4:$L$507="✅ Finalizado")*IF($H$4="",1,TEXT('⏱️ Entrada e Saída'!$F$4:$F$507,"dd/mm")=TEXT($H$4,"dd/mm"))*IFERROR(VALUE('⏱️ Entrada e Saída'!$K$4:$K$507),0))) -> 0
A28: ='📋 Empresas'!B14 -> LINQ | B28: =IF(OR(A28="",A28=0),"",SUMPRODUCT(('⏱️ Entrada e Saída'!$C$4:$C$507=A28)*IF($H$4="",1,TEXT('⏱️ Entrada e Saída'!$F$4:$F$507,"DD/MM")=TEXT($H$4,"DD/MM")))) -> 0 | C28: =IF(OR(A28="",A28=0),"",SUMPRODUCT(('⏱️ Entrada e Saída'!$C$4:$C$507=A28)*('⏱️ Entrada e Saída'!$H$4:$H$507<>"")*('⏱️ Entrada e Saída'!$J$4:$J$507="")*IF($H$4="",1,TEXT('⏱️ Entrada e Saída'!$F$4:$F$507,"DD/MM")=TEXT($H$4,"DD/MM")))) -> 0 | D28: =IF(OR(A28="",A28=0),"",SUMPRODUCT(('⏱️ Entrada e Saída'!$C$4:$C$507=A28)*('⏱️ Entrada e Saída'!$H$4:$H$507<>"")*('⏱️ Entrada e Saída'!$J$4:$J$507<>"")*IF($H$4="",1,TEXT('⏱️ Entrada e Saída'!$F$4:$F$507,"DD/MM")=TEXT($H$4,"DD/MM")))) -> 0 | E28: =IF(OR(A28="",A28=0,B28=""),"",B28-C28-D28) -> 0 | F28: =IF(OR(A28="",A28=0,B28=0,B28=""),"",(C28+D28)/B28) | G28: =IF(OR(A28="",A28=0),"",SUMPRODUCT(('⏱️ Entrada e Saída'!$C$4:$C$507=A28)*('⏱️ Entrada e Saída'!$L$4:$L$507="✅ Finalizado")*IF($H$4="",1,TEXT('⏱️ Entrada e Saída'!$F$4:$F$507,"dd/mm")=TEXT($H$4,"dd/mm"))*IFERROR(VALUE('⏱️ Entrada e Saída'!$K$4:$K$507),0))) -> 0
A29: ='📋 Empresas'!B15 -> ELEMENT | B29: =IF(OR(A29="",A29=0),"",SUMPRODUCT(('⏱️ Entrada e Saída'!$C$4:$C$507=A29)*IF($H$4="",1,TEXT('⏱️ Entrada e Saída'!$F$4:$F$507,"DD/MM")=TEXT($H$4,"DD/MM")))) -> 0 | C29: =IF(OR(A29="",A29=0),"",SUMPRODUCT(('⏱️ Entrada e Saída'!$C$4:$C$507=A29)*('⏱️ Entrada e Saída'!$H$4:$H$507<>"")*('⏱️ Entrada e Saída'!$J$4:$J$507="")*IF($H$4="",1,TEXT('⏱️ Entrada e Saída'!$F$4:$F$507,"DD/MM")=TEXT($H$4,"DD/MM")))) -> 0 | D29: =IF(OR(A29="",A29=0),"",SUMPRODUCT(('⏱️ Entrada e Saída'!$C$4:$C$507=A29)*('⏱️ Entrada e Saída'!$H$4:$H$507<>"")*('⏱️ Entrada e Saída'!$J$4:$J$507<>"")*IF($H$4="",1,TEXT('⏱️ Entrada e Saída'!$F$4:$F$507,"DD/MM")=TEXT($H$4,"DD/MM")))) -> 0 | E29: =IF(OR(A29="",A29=0,B29=""),"",B29-C29-D29) -> 0 | F29: =IF(OR(A29="",A29=0,B29=0,B29=""),"",(C29+D29)/B29) | G29: =IF(OR(A29="",A29=0),"",SUMPRODUCT(('⏱️ Entrada e Saída'!$C$4:$C$507=A29)*('⏱️ Entrada e Saída'!$L$4:$L$507="✅ Finalizado")*IF($H$4="",1,TEXT('⏱️ Entrada e Saída'!$F$4:$F$507,"dd/mm")=TEXT($H$4,"dd/mm"))*IFERROR(VALUE('⏱️ Entrada e Saída'!$K$4:$K$507),0))) -> 0
... A70: ='📋 Empresas'!B56 -> PUBLIC ADDRESS | B70: =IF(OR(A70="",A70=0),"",SUMPRODUCT(('⏱️ Entrada e Saída'!$C$4:$C$507=A70)*IF($H$4="",1,TEXT('⏱️ Entrada e Saída'!$F$4:$F$507,"DD/MM")=TEXT($H$4,"DD/MM")))) -> 0 | C70: =IF(OR(A70="",A70=0),"",SUMPRODUCT(('⏱️ Entrada e Saída'!$C$4:$C$507=A70)*('⏱️ Entrada e Saída'!$H$4:$H$507<>"")*('⏱️ Entrada e Saída'!$J$4:$J$507="")*IF($H$4="",1,TEXT('⏱️ Entrada e Saída'!$F$4:$F$507,"DD/MM")=TEXT($H$4,"DD/MM")))) -> 0 | D70: =IF(OR(A70="",A70=0),"",SUMPRODUCT(('⏱️ Entrada e Saída'!$C$4:$C$507=A70)*('⏱️ Entrada e Saída'!$H$4:$H$507<>"")*('⏱️ Entrada e Saída'!$J$4:$J$507<>"")*IF($H$4="",1,TEXT('⏱️ Entrada e Saída'!$F$4:$F$507,"DD/MM")=TEXT($H$4,"DD/MM")))) -> 0 | E70: =IF(OR(A70="",A70=0,B70=""),"",B70-C70-D70) -> 0 | F70: =IF(OR(A70="",A70=0,B70=0,B70=""),"",(C70+D70)/B70) | G70: =IF(OR(A70="",A70=0),"",SUMPRODUCT(('⏱️ Entrada e Saída'!$C$4:$C$507=A70)*('⏱️ Entrada e Saída'!$L$4:$L$507="✅ Finalizado")*IF($H$4="",1,TEXT('⏱️ Entrada e Saída'!$F$4:$F$507,"dd/mm")=TEXT($H$4,"dd/mm"))*IFERROR(VALUE('⏱️ Entrada e Saída'!$K$4:$K$507),0))) -> 0
A72: 📌 INSTRUÇÕES DE USO
A73: 1. | B73: Aba '📋 Empresas': cadastre todas as empresas prestadoras.
A74: 2. | B74: Aba '👥 Funcionários': cadastre funcionários. Use o dropdown para selecionar a empresa.
A75: 3. | B75: Aba '⏱️ Entrada e Saída': selecione o FUNCIONÁRIO pelo dropdown (col B). EMPRESA, FUNÇÃO e COORD preenchem automaticamente.
A76: 4. | B76: Registre a DATA e clique nos campos de ENTRADA / SAÍDA para registrar o horário (formato HH:MM).
A77: 5. | B77: As colunas HORAS e STATUS são calculadas automaticamente.
A78: 6. | B78: Neste painel, use a célula amarela H3/H4 para filtrar por data. Vazio = todos os dias.

Sheet ✉️ Mensagem Padrão
A1: ✉️ MODELO DE MENSAGEM — CREDENCIAMENTO
A6: 📢 | B6: MENSAGEM PADRÃO PARA ENVIO ÀS EMPRESAS:
B8: Prezado(a) responsável,
B10: Peço que todas as empresas encaminhem os dados completos dos colaboradores que irão
B11: participar do credenciamento, preenchendo todas as informações corretamente e sem
B12: faltar nenhum dado.
B14: Ressalto também que, caso haja qualquer alteração de colaborador, substituição ou
B15: mudança de informações, é indispensável que seja avisado com antecedência, para
B16: evitar problemas no credenciamento e no acesso ao evento.
B18: Todos os colaboradores que irão trabalhar precisam estar devidamente informados na
B19: lista, com os dados corretos e atualizados.
B21: Conto com a colaboração de todos para mantermos a organização e agilidade no processo.
B22: Obrigado!
A24: 🚨 | B24: ATENÇÃO: COLOQUEM O NOME DA EMPRESA, RESPONSÁVEL E DESTAQUEM QUEM SÃO OS
B25: COORDENADORES, PARA QUE NÃO HAJA NENHUMA DIVERGÊNCIA NO CREDENCIAMENTO! 🚨
A27: 📋 | B27: DADOS NECESSÁRIOS POR COLABORADOR:
A29: ✅ | B29: Nome completo
A30: ✅ | B30: CPF
A31: ✅ | B31: Função / Cargo
A32: ✅ | B32: Área de acesso
A33: ✅ | B33: Telefone de contato
A34: ✅ | B34: Indicar se é COORDENADOR (SIM / NÃO)
A35: ✅ | B35: Horário previsto de entrada e saída
A37: ⚠️ | B37: Informações incompletas ou divergentes podem impedir o acesso ao evento.
